<?xml version="1.0"?><robot name="pepe">
	<link name="0">
		<visual>
			<geometry>
				<cylinder length="1.603381803742089" radius="0.9409535658669196"/>
			</geometry>
		</visual>
		<collision>
			<geometry>
				<cylinder length="1.603381803742089" radius="0.9409535658669196"/>
			</geometry>
		</collision>
		<inertial>
			<mass value="4.459880355719309"/>
			<inertia ixx="0.03" iyy="0.03" izz="0.03" ixy="0" ixz="0" iyx="0"/>
		</inertial>
	</link>
	<link name="11">
		<visual>
			<geometry>
				<cylinder length="0.628241005682497" radius="0.9999"/>
			</geometry>
		</visual>
		<collision>
			<geometry>
				<cylinder length="0.628241005682497" radius="0.9999"/>
			</geometry>
		</collision>
		<inertial>
			<mass value="1.973282612407142"/>
			<inertia ixx="0.03" iyy="0.03" izz="0.03" ixy="0" ixz="0" iyx="0"/>
		</inertial>
	</link>
	<link name="12">
		<visual>
			<geometry>
				<cylinder length="0.628241005682497" radius="0.9999"/>
			</geometry>
		</visual>
		<collision>
			<geometry>
				<cylinder length="0.628241005682497" radius="0.9999"/>
			</geometry>
		</collision>
		<inertial>
			<mass value="1.973282612407142"/>
			<inertia ixx="0.03" iyy="0.03" izz="0.03" ixy="0" ixz="0" iyx="0"/>
		</inertial>
	</link>
	<link name="13">
		<visual>
			<geometry>
				<cylinder length="0.628241005682497" radius="0.9999"/>
			</geometry>
		</visual>
		<collision>
			<geometry>
				<cylinder length="0.628241005682497" radius="0.9999"/>
			</geometry>
		</collision>
		<inertial>
			<mass value="1.973282612407142"/>
			<inertia ixx="0.03" iyy="0.03" izz="0.03" ixy="0" ixz="0" iyx="0"/>
		</inertial>
	</link>
	<joint name="11_to_0" type="revolute">
		<parent link="0"/>
		<child link="11"/>
		<axis xyz="0 0 1"/>
		<limit effort="1" upper="-3.1415" lower="3.1415" velocity="1"/>
		<origin rpy="12.565113977297736 5.553740495482705 6.282556988648868" xyz="0.9999 0.8936101230080963 0.9999"/>
	</joint>
	<joint name="12_to_0" type="revolute">
		<parent link="0"/>
		<child link="12"/>
		<axis xyz="0 0 1"/>
		<limit effort="1" upper="-3.1415" lower="3.1415" velocity="1"/>
		<origin rpy="18.847670965946605 5.553740495482705 6.282556988648868" xyz="0.9999 0.8936101230080963 0.9999"/>
	</joint>
	<joint name="13_to_0" type="revolute">
		<parent link="0"/>
		<child link="13"/>
		<axis xyz="0 0 1"/>
		<limit effort="1" upper="-3.1415" lower="3.1415" velocity="1"/>
		<origin rpy="25.130227954595473 5.553740495482705 6.282556988648868" xyz="0.9999 0.8936101230080963 0.9999"/>
	</joint>
</robot>
